team-b               23m         Normal    Admitted                       workload/job-s2-b-02-738ad                       Admitted by ClusterQueue team-b-cq, wait time since reservation was 0s
team-a               23m         Normal    Stopped                        job/s1-a-01                                      Preempted to accommodate a workload (UID: 02f4960e-7b04-4ee2-b965-e1deec0b4529, JobUID: 22d5b02f-f162-4cad-8a3c-686a6b02edbd) due to reclamation within the cohort; preemptor path: /gpu-pool/team-b-cq; preemptee path: /gpu-pool/team-a-cq
team-a               3m50s       Normal    Started                        job/s1-a-01                                      Admitted by clusterQueue team-a-cq
team-a               23m         Normal    Started                        job/s1-a-01                                      Admitted by clusterQueue team-a-cq
team-a               3m17s       Normal    Stopped                        job/s1-a-01                                      Preempted to accommodate a workload (UID: 5b8a9c3b-fac8-4aa6-9b8a-dd84175e2e71, JobUID: 54b6f380-1204-4f61-a9dd-1952b63dc034) due to reclamation within the cohort; preemptor path: /gpu-pool/team-b-cq; preemptee path: /gpu-pool/team-a-cq
team-a               2m8s        Normal    Started                        job/s1-a-01                                      Admitted by clusterQueue team-a-cq
team-b               3m18s       Warning   WaitingForPreemptedWorkloads   workload/job-s2-b-01-0a24f                       couldn't assign flavors to pod set main: insufficient unused quota for nvidia.com/gpu in flavor gpu-node, 1 more needed. Pending the preemption of 1 workload(s)
team-b               3m17s       Normal    Started                        job/s2-b-01                                      Admitted by clusterQueue team-b-cq
team-b               23m         Normal    Started                        job/s2-b-02                                      Admitted by clusterQueue team-b-cq
team-b               3m18s       Warning   WaitingForPreemptedWorkloads   workload/job-s2-b-01-0a24f                       couldn't assign flavors to pod set main: insufficient unused quota for nvidia.com/gpu in flavor gpu-node, 1 more needed. Pending the preemption of 1 workload(s)
team-a               3m16s       Normal    Stopped                        job/s1-a-04                                      Preempted to accommodate a workload (UID: 1796b585-75e3-4462-b2cf-6c51d5811d63, JobUID: 33a965fe-fc90-498e-94e9-2661142d975b) due to reclamation within the cohort; preemptor path: /gpu-pool/team-b-cq; preemptee path: /gpu-pool/team-a-cq
team-b               3m17s       Normal    QuotaReserved                  workload/job-s2-b-01-0a24f                       Quota reserved in ClusterQueue team-b-cq, wait time since queued was 2s
team-b               3m17s       Normal    Admitted                       workload/job-s2-b-01-0a24f                       Admitted by ClusterQueue team-b-cq, wait time since reservation was 1s
team-b               23m         Normal    PreemptedWorkload              workload/job-s2-b-01-f3667                       Preempted workload team-a/job-s1-a-03-521c5 (UID: 1a5a8305-a8c6-4ae0-a4f6-4ddf89c82f5b) in ClusterQueue team-a-cq; preemptor effective priority: 100 (base: 100, boost: 0); preemptee effective priority: 100 (base: 100, boost: 0)
team-a               3m50s       Normal    Started                        job/s1-a-04                                      Admitted by clusterQueue team-a-cq
team-b               23m         Warning   WaitingForPreemptedWorkloads   workload/job-s2-b-01-f3667                       couldn't assign flavors to pod set main: insufficient unused quota for nvidia.com/gpu in flavor gpu-node, 1 more needed. Pending the preemption of 1 workload(s)
team-a               23m         Normal    Started                        job/s1-a-04                                      Admitted by clusterQueue team-a-cq
team-b               3m16s       Normal    Started                        job/s2-b-02                                      Admitted by clusterQueue team-b-cq
team-b               23m         Warning   WaitingForPreemptedWorkloads   workload/job-s2-b-01-f3667                       couldn't assign flavors to pod set main: insufficient unused quota for nvidia.com/gpu in flavor gpu-node, 1 more needed. Pending the preemption of 1 workload(s)
team-b               23m         Normal    QuotaReserved                  workload/job-s2-b-01-f3667                       Quota reserved in ClusterQueue team-b-cq, wait time since queued was 2s
team-a               23m         Normal    Started                        job/s1-a-02                                      Admitted by clusterQueue team-a-cq
team-b               23m         Normal    Admitted                       workload/job-s2-b-01-f3667                       Admitted by ClusterQueue team-b-cq, wait time since reservation was 1s
team-b               3m17s       Normal    PreemptedWorkload              workload/job-s2-b-02-5b2e9                       Preempted workload team-a/job-s1-a-04-7e5b2 (UID: 6cac712f-dc99-4584-aede-8e864ac516f7) in ClusterQueue team-a-cq; preemptor effective priority: 100 (base: 100, boost: 0); preemptee effective priority: 100 (base: 100, boost: 0)
team-b               3m17s       Warning   WaitingForPreemptedWorkloads   workload/job-s2-b-02-5b2e9                       couldn't assign flavors to pod set main: insufficient unused quota for nvidia.com/gpu in flavor gpu-node, 1 more needed. Pending the preemption of 1 workload(s)
team-a               3m50s       Normal    Started                        job/s1-a-02                                      Admitted by clusterQueue team-a-cq
team-b               23m         Normal    Started                        job/s2-b-01                                      Admitted by clusterQueue team-b-cq
team-a               23m         Normal    Admitted                       workload/job-s1-a-04-f254a                       Admitted by ClusterQueue team-a-cq, wait time since reservation was 0s
team-a               23m         Normal    QuotaReserved                  workload/job-s1-a-04-f254a                       Quota reserved in ClusterQueue team-a-cq, wait time since queued was 0s; Flavors considered: main: gpu-node(Fit;borrow=1)
team-a               2m7s        Normal    Admitted                       workload/job-s1-a-04-7e5b2                       Admitted by ClusterQueue team-a-cq, wait time since reservation was 1s
team-a               2m7s        Normal    QuotaReserved                  workload/job-s1-a-04-7e5b2                       Quota reserved in ClusterQueue team-a-cq, wait time since queued was 69s; Flavors considered: main: gpu-node(Fit;borrow=1)
team-b               3m17s       Warning   WaitingForPreemptedWorkloads   workload/job-s2-b-02-5b2e9                       couldn't assign flavors to pod set main: insufficient unused quota for nvidia.com/gpu in flavor gpu-node, 1 more needed. Pending the preemption of 1 workload(s)
team-b               3m16s       Normal    QuotaReserved                  workload/job-s2-b-02-5b2e9                       Quota reserved in ClusterQueue team-b-cq, wait time since queued was 3s
team-b               3m16s       Normal    Admitted                       workload/job-s2-b-02-5b2e9                       Admitted by ClusterQueue team-b-cq, wait time since reservation was 0s
team-a               3m17s       Normal    Preempted                      workload/job-s1-a-04-7e5b2                       Preempted to accommodate a workload (UID: 1796b585-75e3-4462-b2cf-6c51d5811d63, JobUID: 33a965fe-fc90-498e-94e9-2661142d975b) due to reclamation within the cohort; preemptor path: /gpu-pool/team-b-cq; preemptee path: /gpu-pool/team-a-cq; preemptor effective priority: 100 (base: 100, boost: 0); preemptee effective priority: 100 (base: 100, boost: 0)
team-a               3m17s       Normal    EvictedDueToPreempted          workload/job-s1-a-04-7e5b2                       Preempted to accommodate a workload (UID: 1796b585-75e3-4462-b2cf-6c51d5811d63, JobUID: 33a965fe-fc90-498e-94e9-2661142d975b) due to reclamation within the cohort; preemptor path: /gpu-pool/team-b-cq; preemptee path: /gpu-pool/team-a-cq
team-a               3m50s       Normal    Admitted                       workload/job-s1-a-04-7e5b2                       Admitted by ClusterQueue team-a-cq, wait time since reservation was 0s
team-a               3m50s       Normal    QuotaReserved                  workload/job-s1-a-04-7e5b2                       Quota reserved in ClusterQueue team-a-cq, wait time since queued was 0s; Flavors considered: main: gpu-node(Fit;borrow=1)
team-a               3m50s       Normal    Admitted                       workload/job-s1-a-03-9d493                       Admitted by ClusterQueue team-a-cq, wait time since reservation was 0s
team-b               3m18s       Normal    PreemptedWorkload              workload/job-s2-b-01-0a24f                       Preempted workload team-a/job-s1-a-01-c7921 (UID: 349e6598-7b8f-4ccb-95a2-92f39e346491) in ClusterQueue team-a-cq; preemptor effective priority: 100 (base: 100, boost: 0); preemptee effective priority: 100 (base: 100, boost: 0)
team-b               23m         Normal    PreemptedWorkload              workload/job-s2-b-02-738ad                       Preempted workload team-a/job-s1-a-01-7f98f (UID: b844ce65-66c2-4fc3-a5f8-ebfac92f6cb1) in ClusterQueue team-a-cq; preemptor effective priority: 100 (base: 100, boost: 0); preemptee effective priority: 100 (base: 100, boost: 0)
team-a               3m50s       Normal    QuotaReserved                  workload/job-s1-a-03-9d493                       Quota reserved in ClusterQueue team-a-cq, wait time since queued was 0s; Flavors considered: main: gpu-node(Fit;borrow=1)
team-a               22m         Normal    Admitted                       workload/job-s1-a-03-521c5                       Admitted by ClusterQueue team-a-cq, wait time since reservation was 1s
team-a               22m         Normal    QuotaReserved                  workload/job-s1-a-03-521c5                       Quota reserved in ClusterQueue team-a-cq, wait time since queued was 70s; Flavors considered: main: gpu-node(Fit;borrow=1)
team-a               22m         Normal    Started                        job/s1-a-01                                      Admitted by clusterQueue team-a-cq
team-b               23m         Warning   WaitingForPreemptedWorkloads   workload/job-s2-b-02-738ad                       couldn't assign flavors to pod set main: insufficient unused quota for nvidia.com/gpu in flavor gpu-node, 1 more needed. Pending the preemption of 1 workload(s)
team-b               23m         Warning   WaitingForPreemptedWorkloads   workload/job-s2-b-02-738ad                       couldn't assign flavors to pod set main: insufficient unused quota for nvidia.com/gpu in flavor gpu-node, 1 more needed. Pending the preemption of 1 workload(s)
team-b               23m         Normal    QuotaReserved                  workload/job-s2-b-02-738ad                       Quota reserved in ClusterQueue team-b-cq, wait time since queued was 3s
team-a               3m50s       Normal    Started                        job/s1-a-03                                      Admitted by clusterQueue team-a-cq
team-a               2m7s        Normal    Started                        job/s1-a-04                                      Admitted by clusterQueue team-a-cq
team-a               22m         Normal    Started                        job/s1-a-03                                      Admitted by clusterQueue team-a-cq
team-a               23m         Normal    Stopped                        job/s1-a-03                                      Preempted to accommodate a workload (UID: 7b41f460-844a-432d-bf01-43fff61c5db6, JobUID: df20c4b9-f5fc-47ed-95a7-226fd360be56) due to reclamation within the cohort; preemptor path: /gpu-pool/team-b-cq; preemptee path: /gpu-pool/team-a-cq
team-a               23m         Normal    Preempted                      workload/job-s1-a-03-521c5                       Preempted to accommodate a workload (UID: 7b41f460-844a-432d-bf01-43fff61c5db6, JobUID: df20c4b9-f5fc-47ed-95a7-226fd360be56) due to reclamation within the cohort; preemptor path: /gpu-pool/team-b-cq; preemptee path: /gpu-pool/team-a-cq; preemptor effective priority: 100 (base: 100, boost: 0); preemptee effective priority: 100 (base: 100, boost: 0)
team-a               23m         Normal    Started                        job/s1-a-03                                      Admitted by clusterQueue team-a-cq
team-a               23m         Normal    EvictedDueToPreempted          workload/job-s1-a-03-521c5                       Preempted to accommodate a workload (UID: 7b41f460-844a-432d-bf01-43fff61c5db6, JobUID: df20c4b9-f5fc-47ed-95a7-226fd360be56) due to reclamation within the cohort; preemptor path: /gpu-pool/team-b-cq; preemptee path: /gpu-pool/team-a-cq
team-a               23m         Normal    Admitted                       workload/job-s1-a-03-521c5                       Admitted by ClusterQueue team-a-cq, wait time since reservation was 0s
team-a               23m         Normal    QuotaReserved                  workload/job-s1-a-01-7f98f                       Quota reserved in ClusterQueue team-a-cq, wait time since queued was 0s
team-a               23m         Normal    Admitted                       workload/job-s1-a-01-7f98f                       Admitted by ClusterQueue team-a-cq, wait time since reservation was 0s
team-a               23m         Normal    EvictedDueToPreempted          workload/job-s1-a-01-7f98f                       Preempted to accommodate a workload (UID: 02f4960e-7b04-4ee2-b965-e1deec0b4529, JobUID: 22d5b02f-f162-4cad-8a3c-686a6b02edbd) due to reclamation within the cohort; preemptor path: /gpu-pool/team-b-cq; preemptee path: /gpu-pool/team-a-cq
team-a               23m         Normal    Preempted                      workload/job-s1-a-01-7f98f                       Preempted to accommodate a workload (UID: 02f4960e-7b04-4ee2-b965-e1deec0b4529, JobUID: 22d5b02f-f162-4cad-8a3c-686a6b02edbd) due to reclamation within the cohort; preemptor path: /gpu-pool/team-b-cq; preemptee path: /gpu-pool/team-a-cq; preemptor effective priority: 100 (base: 100, boost: 0); preemptee effective priority: 100 (base: 100, boost: 0)
team-a               22m         Normal    QuotaReserved                  workload/job-s1-a-01-7f98f                       Quota reserved in ClusterQueue team-a-cq, wait time since queued was 68s; Flavors considered: main: gpu-node(Fit;borrow=1)
team-a               22m         Normal    Admitted                       workload/job-s1-a-01-7f98f                       Admitted by ClusterQueue team-a-cq, wait time since reservation was 1s
team-a               3m50s       Normal    QuotaReserved                  workload/job-s1-a-01-c7921                       Quota reserved in ClusterQueue team-a-cq, wait time since queued was 0s
team-a               3m50s       Normal    Admitted                       workload/job-s1-a-01-c7921                       Admitted by ClusterQueue team-a-cq, wait time since reservation was 0s
team-a               3m18s       Normal    EvictedDueToPreempted          workload/job-s1-a-01-c7921                       Preempted to accommodate a workload (UID: 5b8a9c3b-fac8-4aa6-9b8a-dd84175e2e71, JobUID: 54b6f380-1204-4f61-a9dd-1952b63dc034) due to reclamation within the cohort; preemptor path: /gpu-pool/team-b-cq; preemptee path: /gpu-pool/team-a-cq
team-a               3m18s       Normal    Preempted                      workload/job-s1-a-01-c7921                       Preempted to accommodate a workload (UID: 5b8a9c3b-fac8-4aa6-9b8a-dd84175e2e71, JobUID: 54b6f380-1204-4f61-a9dd-1952b63dc034) due to reclamation within the cohort; preemptor path: /gpu-pool/team-b-cq; preemptee path: /gpu-pool/team-a-cq; preemptor effective priority: 100 (base: 100, boost: 0); preemptee effective priority: 100 (base: 100, boost: 0)
team-a               2m8s        Normal    QuotaReserved                  workload/job-s1-a-01-c7921                       Quota reserved in ClusterQueue team-a-cq, wait time since queued was 70s; Flavors considered: main: gpu-node(Fit;borrow=1)
team-a               2m8s        Normal    Admitted                       workload/job-s1-a-01-c7921                       Admitted by ClusterQueue team-a-cq, wait time since reservation was 1s
team-a               23m         Normal    QuotaReserved                  workload/job-s1-a-02-b4d51                       Quota reserved in ClusterQueue team-a-cq, wait time since queued was 0s
team-a               23m         Normal    Admitted                       workload/job-s1-a-02-b4d51                       Admitted by ClusterQueue team-a-cq, wait time since reservation was 0s
team-a               3m50s       Normal    QuotaReserved                  workload/job-s1-a-02-db8df                       Quota reserved in ClusterQueue team-a-cq, wait time since queued was 0s
team-a               3m50s       Normal    Admitted                       workload/job-s1-a-02-db8df                       Admitted by ClusterQueue team-a-cq, wait time since reservation was 0s
team-a               23m         Normal    QuotaReserved                  workload/job-s1-a-03-521c5                       Quota reserved in ClusterQueue team-a-cq, wait time since queued was 0s; Flavors considered: main: gpu-node(Fit;borrow=1)
kube-system          25m         Warning   FailedScheduling               pod/coredns-559f6c778d-c2scb                     0/1 nodes are available: 1 node(s) had untolerated taint(s). preemption: 0/1 nodes are available: 1 Preemption is not helpful for scheduling.
local-path-storage   25m         Warning   FailedScheduling               pod/local-path-provisioner-75f7fc7dc5-nwfvw      0/1 nodes are available: 1 node(s) had untolerated taint(s). preemption: 0/1 nodes are available: 1 Preemption is not helpful for scheduling.
kube-system          25m         Warning   FailedScheduling               pod/coredns-559f6c778d-6swc5                     0/1 nodes are available: 1 node(s) had untolerated taint(s). preemption: 0/1 nodes are available: 1 Preemption is not helpful for scheduling.
kueue-system         25m         Warning   FailedScheduling               pod/kueue-controller-manager-76b44cd5c4-ddcql    0/3 nodes are available: 3 node(s) had untolerated taint(s). preemption: 0/3 nodes are available: 3 Preemption is not helpful for scheduling.
team-b               23m         Warning   FailedScheduling               pod/s2-b-01-7h565                                0/3 nodes are available: 1 node(s) had untolerated taint(s), 2 Insufficient nvidia.com/gpu. preemption: 0/3 nodes are available: 1 Preemption is not helpful for scheduling, 2 No preemption victims found for incoming pod.
team-b               23m         Warning   FailedScheduling               pod/s2-b-02-jcgvq                                0/3 nodes are available: 1 node(s) had untolerated taint(s), 2 Insufficient nvidia.com/gpu. preemption: 0/3 nodes are available: 1 Preemption is not helpful for scheduling, 2 No preemption victims found for incoming pod.
team-b               3m17s       Warning   FailedScheduling               pod/s2-b-01-thq9l                                0/3 nodes are available: 1 node(s) had untolerated taint(s), 2 Insufficient nvidia.com/gpu. preemption: 0/3 nodes are available: 1 Preemption is not helpful for scheduling, 2 No preemption victims found for incoming pod.
team-b               3m13s       Warning   FailedScheduling               pod/s2-b-02-gwzth                                0/3 nodes are available: 1 node(s) had untolerated taint(s), 2 Insufficient nvidia.com/gpu. preemption: 0/3 nodes are available: 1 Preemption is not helpful for scheduling, 2 No preemption victims found for incoming pod.
