team-b        19m         Normal    PreemptedWorkload              workload/job-s2-b-01-9d30d      Preempted workload team-a/job-s1-a-01-dfadb (UID: 23b42ed2-3e06-4979-98f6-8c2316f37524) in ClusterQueue team-a-cq; preemptor effective priority: 100 (base: 100, boost: 0); preemptee effective priority: 100 (base: 100, boost: 0)
team-a        20m         Normal    Started                        job/s1-a-02                     Admitted by clusterQueue team-a-cq
team-a        13m         Normal    Started                        job/s4-a-02                     Admitted by clusterQueue team-a-cq
team-a        8m27s       Normal    QuotaReserved                  workload/job-s1-a-01-11635      Quota reserved in ClusterQueue team-a-cq, wait time since queued was 0s
team-a        8m27s       Normal    Admitted                       workload/job-s1-a-01-11635      Admitted by ClusterQueue team-a-cq, wait time since reservation was 0s
team-a        20m         Normal    QuotaReserved                  workload/job-s1-a-01-dfadb      Quota reserved in ClusterQueue team-a-cq, wait time since queued was 1s
team-a        20m         Normal    Admitted                       workload/job-s1-a-01-dfadb      Admitted by ClusterQueue team-a-cq, wait time since reservation was 1s
team-a        19m         Normal    EvictedDueToPreempted          workload/job-s1-a-01-dfadb      Preempted to accommodate a workload (UID: d64a966b-b291-4971-8605-83cf5d4a68ae, JobUID: 184db061-5915-4196-a699-b08f255b7b60) due to reclamation within the cohort; preemptor path: /gpu-pool/team-b-cq; preemptee path: /gpu-pool/team-a-cq
team-a        19m         Normal    Preempted                      workload/job-s1-a-01-dfadb      Preempted to accommodate a workload (UID: d64a966b-b291-4971-8605-83cf5d4a68ae, JobUID: 184db061-5915-4196-a699-b08f255b7b60) due to reclamation within the cohort; preemptor path: /gpu-pool/team-b-cq; preemptee path: /gpu-pool/team-a-cq; preemptor effective priority: 100 (base: 100, boost: 0); preemptee effective priority: 100 (base: 100, boost: 0)
team-a        18m         Normal    QuotaReserved                  workload/job-s1-a-01-dfadb      Quota reserved in ClusterQueue team-a-cq, wait time since queued was 62s; Flavors considered: main: gpu-node(Fit;borrow=1)
team-a        18m         Normal    Admitted                       workload/job-s1-a-01-dfadb      Admitted by ClusterQueue team-a-cq, wait time since reservation was 0s
team-a        32m         Normal    QuotaReserved                  workload/job-s1-a-01-f3da4      Quota reserved in ClusterQueue team-a-cq, wait time since queued was 0s
team-a        32m         Normal    Admitted                       workload/job-s1-a-01-f3da4      Admitted by ClusterQueue team-a-cq, wait time since reservation was 0s
team-a        31m         Normal    EvictedDueToPreempted          workload/job-s1-a-01-f3da4      Preempted to accommodate a workload (UID: 813077fb-6851-4f72-9b25-e107e159191e, JobUID: cc830d49-ddd7-4188-b6c3-ebad619ade6c) due to reclamation within the cohort; preemptor path: /gpu-pool/team-b-cq; preemptee path: /gpu-pool/team-a-cq
team-a        31m         Normal    Preempted                      workload/job-s1-a-01-f3da4      Preempted to accommodate a workload (UID: 813077fb-6851-4f72-9b25-e107e159191e, JobUID: cc830d49-ddd7-4188-b6c3-ebad619ade6c) due to reclamation within the cohort; preemptor path: /gpu-pool/team-b-cq; preemptee path: /gpu-pool/team-a-cq; preemptor effective priority: 100 (base: 100, boost: 0); preemptee effective priority: 100 (base: 100, boost: 0)
team-a        30m         Normal    QuotaReserved                  workload/job-s1-a-01-f3da4      Quota reserved in ClusterQueue team-a-cq, wait time since queued was 63s; Flavors considered: main: gpu-node(Fit;borrow=1)
team-a        30m         Normal    Admitted                       workload/job-s1-a-01-f3da4      Admitted by ClusterQueue team-a-cq, wait time since reservation was 1s
team-a        8m27s       Normal    QuotaReserved                  workload/job-s1-a-02-a2320      Quota reserved in ClusterQueue team-a-cq, wait time since queued was 0s
team-a        8m27s       Normal    Admitted                       workload/job-s1-a-02-a2320      Admitted by ClusterQueue team-a-cq, wait time since reservation was 0s
team-a        7m57s       Normal    EvictedDueToPreempted          workload/job-s1-a-02-a2320      Preempted to accommodate a workload (UID: 255f47e5-f138-4028-a784-ceb9eb01cc6c, JobUID: 8e73496a-b30d-4dd4-9eca-23cc62e6aeff) due to reclamation within the cohort; preemptor path: /gpu-pool/team-b-cq; preemptee path: /gpu-pool/team-a-cq
team-a        7m57s       Normal    Preempted                      workload/job-s1-a-02-a2320      Preempted to accommodate a workload (UID: 255f47e5-f138-4028-a784-ceb9eb01cc6c, JobUID: 8e73496a-b30d-4dd4-9eca-23cc62e6aeff) due to reclamation within the cohort; preemptor path: /gpu-pool/team-b-cq; preemptee path: /gpu-pool/team-a-cq; preemptor effective priority: 100 (base: 100, boost: 0); preemptee effective priority: 100 (base: 100, boost: 0)
team-a        6m54s       Normal    QuotaReserved                  workload/job-s1-a-02-a2320      Quota reserved in ClusterQueue team-a-cq, wait time since queued was 63s; Flavors considered: main: gpu-node(Fit;borrow=1)
team-a        6m54s       Normal    Admitted                       workload/job-s1-a-02-a2320      Admitted by ClusterQueue team-a-cq, wait time since reservation was 1s
team-a        20m         Normal    QuotaReserved                  workload/job-s1-a-02-a3b8b      Quota reserved in ClusterQueue team-a-cq, wait time since queued was 1s
team-a        20m         Normal    Admitted                       workload/job-s1-a-02-a3b8b      Admitted by ClusterQueue team-a-cq, wait time since reservation was 1s
team-a        32m         Normal    QuotaReserved                  workload/job-s1-a-02-c1d3a      Quota reserved in ClusterQueue team-a-cq, wait time since queued was 0s
team-a        32m         Normal    Admitted                       workload/job-s1-a-02-c1d3a      Admitted by ClusterQueue team-a-cq, wait time since reservation was 0s
team-a        31m         Normal    EvictedDueToPreempted          workload/job-s1-a-02-c1d3a      Preempted to accommodate a workload (UID: ff1bdb74-d239-4fc0-8909-d3727254066e, JobUID: 3cea9334-971d-46ce-abaf-92e7178c26f8) due to reclamation within the cohort; preemptor path: /gpu-pool/team-b-cq; preemptee path: /gpu-pool/team-a-cq
team-a        31m         Normal    Preempted                      workload/job-s1-a-02-c1d3a      Preempted to accommodate a workload (UID: ff1bdb74-d239-4fc0-8909-d3727254066e, JobUID: 3cea9334-971d-46ce-abaf-92e7178c26f8) due to reclamation within the cohort; preemptor path: /gpu-pool/team-b-cq; preemptee path: /gpu-pool/team-a-cq; preemptor effective priority: 100 (base: 100, boost: 0); preemptee effective priority: 100 (base: 100, boost: 0)
team-a        30m         Normal    QuotaReserved                  workload/job-s1-a-02-c1d3a      Quota reserved in ClusterQueue team-a-cq, wait time since queued was 63s; Flavors considered: main: gpu-node(Fit;borrow=1)
team-a        30m         Normal    Admitted                       workload/job-s1-a-02-c1d3a      Admitted by ClusterQueue team-a-cq, wait time since reservation was 1s
team-a        8m27s       Normal    QuotaReserved                  workload/job-s1-a-03-7ddb8      Quota reserved in ClusterQueue team-a-cq, wait time since queued was 0s; Flavors considered: main: gpu-node(Fit;borrow=1)
team-a        8m27s       Normal    Admitted                       workload/job-s1-a-03-7ddb8      Admitted by ClusterQueue team-a-cq, wait time since reservation was 0s
team-a        7m56s       Normal    EvictedDueToPreempted          workload/job-s1-a-03-7ddb8      Preempted to accommodate a workload (UID: 2a833217-d9c8-4e9d-a8cd-eb98d862554a, JobUID: fe239855-686a-4ab5-974c-ef89b7c55d1a) due to reclamation within the cohort; preemptor path: /gpu-pool/team-b-cq; preemptee path: /gpu-pool/team-a-cq
team-a        7m56s       Normal    Preempted                      workload/job-s1-a-03-7ddb8      Preempted to accommodate a workload (UID: 2a833217-d9c8-4e9d-a8cd-eb98d862554a, JobUID: fe239855-686a-4ab5-974c-ef89b7c55d1a) due to reclamation within the cohort; preemptor path: /gpu-pool/team-b-cq; preemptee path: /gpu-pool/team-a-cq; preemptor effective priority: 100 (base: 100, boost: 0); preemptee effective priority: 100 (base: 100, boost: 0)
team-a        6m52s       Normal    QuotaReserved                  workload/job-s1-a-03-7ddb8      Quota reserved in ClusterQueue team-a-cq, wait time since queued was 63s; Flavors considered: main: gpu-node(Fit;borrow=1)
team-a        6m52s       Normal    Admitted                       workload/job-s1-a-03-7ddb8      Admitted by ClusterQueue team-a-cq, wait time since reservation was 1s
team-a        20m         Normal    QuotaReserved                  workload/job-s1-a-03-8b776      Quota reserved in ClusterQueue team-a-cq, wait time since queued was 1s; Flavors considered: main: gpu-node(Fit;borrow=1)
team-a        20m         Normal    Admitted                       workload/job-s1-a-03-8b776      Admitted by ClusterQueue team-a-cq, wait time since reservation was 1s
team-a        32m         Normal    QuotaReserved                  workload/job-s1-a-03-d3982      Quota reserved in ClusterQueue team-a-cq, wait time since queued was 0s; Flavors considered: main: gpu-node(Fit;borrow=1)
team-a        32m         Normal    Admitted                       workload/job-s1-a-03-d3982      Admitted by ClusterQueue team-a-cq, wait time since reservation was 0s
team-a        32m         Normal    QuotaReserved                  workload/job-s1-a-04-2b5d1      Quota reserved in ClusterQueue team-a-cq, wait time since queued was 0s; Flavors considered: main: gpu-node(Fit;borrow=1)
team-a        32m         Normal    Admitted                       workload/job-s1-a-04-2b5d1      Admitted by ClusterQueue team-a-cq, wait time since reservation was 0s
team-a        20m         Normal    QuotaReserved                  workload/job-s1-a-04-2fce2      Quota reserved in ClusterQueue team-a-cq, wait time since queued was 1s; Flavors considered: main: gpu-node(Fit;borrow=1)
team-a        20m         Normal    Admitted                       workload/job-s1-a-04-2fce2      Admitted by ClusterQueue team-a-cq, wait time since reservation was 1s
team-a        19m         Normal    EvictedDueToPreempted          workload/job-s1-a-04-2fce2      Preempted to accommodate a workload (UID: e37bba9e-9b8d-40b4-abec-2449d489cb83, JobUID: 3f8c2b68-f2f8-4919-84db-3b462d43c73f) due to reclamation within the cohort; preemptor path: /gpu-pool/team-b-cq; preemptee path: /gpu-pool/team-a-cq
team-a        19m         Normal    Preempted                      workload/job-s1-a-04-2fce2      Preempted to accommodate a workload (UID: e37bba9e-9b8d-40b4-abec-2449d489cb83, JobUID: 3f8c2b68-f2f8-4919-84db-3b462d43c73f) due to reclamation within the cohort; preemptor path: /gpu-pool/team-b-cq; preemptee path: /gpu-pool/team-a-cq; preemptor effective priority: 100 (base: 100, boost: 0); preemptee effective priority: 100 (base: 100, boost: 0)
team-a        18m         Normal    QuotaReserved                  workload/job-s1-a-04-2fce2      Quota reserved in ClusterQueue team-a-cq, wait time since queued was 62s; Flavors considered: main: gpu-node(Fit;borrow=1)
team-a        18m         Normal    Admitted                       workload/job-s1-a-04-2fce2      Admitted by ClusterQueue team-a-cq, wait time since reservation was 0s
team-a        8m27s       Normal    QuotaReserved                  workload/job-s1-a-04-a5354      Quota reserved in ClusterQueue team-a-cq, wait time since queued was 0s; Flavors considered: main: gpu-node(Fit;borrow=1)
team-a        8m27s       Normal    Admitted                       workload/job-s1-a-04-a5354      Admitted by ClusterQueue team-a-cq, wait time since reservation was 0s
team-a        13m         Normal    PreemptedWorkload              workload/job-s3-high-01-03f9c   Preempted workload team-a/job-s3-low-02-1705c (UID: 4ee4a3cc-1c80-483f-804e-4c4343d47ce5) in ClusterQueue team-a-cq; preemptor effective priority: 1000 (base: 1000, boost: 0); preemptee effective priority: 100 (base: 100, boost: 0)
team-a        13m         Warning   WaitingForPreemptedWorkloads   workload/job-s3-high-01-03f9c   couldn't assign flavors to pod set main: insufficient unused quota for nvidia.com/gpu in flavor gpu-node, 1 more needed. Pending the preemption of 1 workload(s)
team-a        13m         Warning   WaitingForPreemptedWorkloads   workload/job-s3-high-01-03f9c   couldn't assign flavors to pod set main: insufficient unused quota for nvidia.com/gpu in flavor gpu-node, 1 more needed. Pending the preemption of 1 workload(s)
team-a        13m         Normal    QuotaReserved                  workload/job-s3-high-01-03f9c   Quota reserved in ClusterQueue team-a-cq, wait time since queued was 2s
team-a        13m         Normal    Admitted                       workload/job-s3-high-01-03f9c   Admitted by ClusterQueue team-a-cq, wait time since reservation was 1s
team-a        25m         Normal    PreemptedWorkload              workload/job-s3-high-01-a64c4   Preempted workload team-a/job-s3-low-02-37e08 (UID: 652f5b8a-d2a4-4189-95c6-e58e9e4a6bcf) in ClusterQueue team-a-cq; preemptor effective priority: 1000 (base: 1000, boost: 0); preemptee effective priority: 100 (base: 100, boost: 0)
team-a        25m         Warning   WaitingForPreemptedWorkloads   workload/job-s3-high-01-a64c4   couldn't assign flavors to pod set main: insufficient unused quota for nvidia.com/gpu in flavor gpu-node, 1 more needed. Pending the preemption of 1 workload(s)
team-a        25m         Warning   WaitingForPreemptedWorkloads   workload/job-s3-high-01-a64c4   couldn't assign flavors to pod set main: insufficient unused quota for nvidia.com/gpu in flavor gpu-node, 1 more needed. Pending the preemption of 1 workload(s)
team-a        25m         Normal    QuotaReserved                  workload/job-s3-high-01-a64c4   Quota reserved in ClusterQueue team-a-cq, wait time since queued was 2s
team-a        25m         Normal    Admitted                       workload/job-s3-high-01-a64c4   Admitted by ClusterQueue team-a-cq, wait time since reservation was 0s
team-a        2m7s        Normal    PreemptedWorkload              workload/job-s3-high-01-ef5f8   Preempted workload team-a/job-s3-low-01-89823 (UID: 5a9dbe0e-ac35-4432-91f2-d21c138a6755) in ClusterQueue team-a-cq; preemptor effective priority: 1000 (base: 1000, boost: 0); preemptee effective priority: 100 (base: 100, boost: 0)
team-a        2m7s        Warning   WaitingForPreemptedWorkloads   workload/job-s3-high-01-ef5f8   couldn't assign flavors to pod set main: insufficient unused quota for nvidia.com/gpu in flavor gpu-node, 1 more needed. Pending the preemption of 1 workload(s)
team-a        2m7s        Warning   WaitingForPreemptedWorkloads   workload/job-s3-high-01-ef5f8   couldn't assign flavors to pod set main: insufficient unused quota for nvidia.com/gpu in flavor gpu-node, 1 more needed. Pending the preemption of 1 workload(s)
team-a        2m5s        Normal    QuotaReserved                  workload/job-s3-high-01-ef5f8   Quota reserved in ClusterQueue team-a-cq, wait time since queued was 2s
team-a        2m5s        Normal    Admitted                       workload/job-s3-high-01-ef5f8   Admitted by ClusterQueue team-a-cq, wait time since reservation was 1s
team-a        13m         Normal    QuotaReserved                  workload/job-s3-low-01-741ec    Quota reserved in ClusterQueue team-a-cq, wait time since queued was 0s
team-a        13m         Normal    Admitted                       workload/job-s3-low-01-741ec    Admitted by ClusterQueue team-a-cq, wait time since reservation was 0s
team-a        2m22s       Normal    QuotaReserved                  workload/job-s3-low-01-89823    Quota reserved in ClusterQueue team-a-cq, wait time since queued was 1s
team-a        2m22s       Normal    Admitted                       workload/job-s3-low-01-89823    Admitted by ClusterQueue team-a-cq, wait time since reservation was 1s
team-a        2m7s        Normal    EvictedDueToPreempted          workload/job-s3-low-01-89823    Preempted to accommodate a workload (UID: 6d2f0a34-2b45-457d-8fdd-aa2292c05e31, JobUID: 703a47be-70fd-46c1-b505-49ae790bc190) due to prioritization in the ClusterQueue; preemptor path: /gpu-pool/team-a-cq; preemptee path: /gpu-pool/team-a-cq
team-a        2m7s        Normal    Preempted                      workload/job-s3-low-01-89823    Preempted to accommodate a workload (UID: 6d2f0a34-2b45-457d-8fdd-aa2292c05e31, JobUID: 703a47be-70fd-46c1-b505-49ae790bc190) due to prioritization in the ClusterQueue; preemptor path: /gpu-pool/team-a-cq; preemptee path: /gpu-pool/team-a-cq; preemptor effective priority: 1000 (base: 1000, boost: 0); preemptee effective priority: 100 (base: 100, boost: 0)
team-a        93s         Normal    QuotaReserved                  workload/job-s3-low-01-89823    Quota reserved in ClusterQueue team-a-cq, wait time since queued was 33s
team-a        93s         Normal    Admitted                       workload/job-s3-low-01-89823    Admitted by ClusterQueue team-a-cq, wait time since reservation was 1s
team-a        26m         Normal    QuotaReserved                  workload/job-s3-low-01-a34d2    Quota reserved in ClusterQueue team-a-cq, wait time since queued was 1s
team-a        26m         Normal    Admitted                       workload/job-s3-low-01-a34d2    Admitted by ClusterQueue team-a-cq, wait time since reservation was 1s
team-a        13m         Normal    QuotaReserved                  workload/job-s3-low-02-1705c    Quota reserved in ClusterQueue team-a-cq, wait time since queued was 0s
team-a        13m         Normal    Admitted                       workload/job-s3-low-02-1705c    Admitted by ClusterQueue team-a-cq, wait time since reservation was 0s
team-a        13m         Normal    EvictedDueToPreempted          workload/job-s3-low-02-1705c    Preempted to accommodate a workload (UID: 2f56e49c-4011-4e39-8752-5023b91b4dc0, JobUID: 324bd808-fefd-4d77-952a-d09e6d2cc3ef) due to prioritization in the ClusterQueue; preemptor path: /gpu-pool/team-a-cq; preemptee path: /gpu-pool/team-a-cq
team-a        13m         Normal    Preempted                      workload/job-s3-low-02-1705c    Preempted to accommodate a workload (UID: 2f56e49c-4011-4e39-8752-5023b91b4dc0, JobUID: 324bd808-fefd-4d77-952a-d09e6d2cc3ef) due to prioritization in the ClusterQueue; preemptor path: /gpu-pool/team-a-cq; preemptee path: /gpu-pool/team-a-cq; preemptor effective priority: 1000 (base: 1000, boost: 0); preemptee effective priority: 100 (base: 100, boost: 0)
team-a        13m         Normal    QuotaReserved                  workload/job-s3-low-02-1705c    Quota reserved in ClusterQueue team-a-cq, wait time since queued was 33s
team-a        13m         Normal    Admitted                       workload/job-s3-low-02-1705c    Admitted by ClusterQueue team-a-cq, wait time since reservation was 1s
team-a        26m         Normal    QuotaReserved                  workload/job-s3-low-02-37e08    Quota reserved in ClusterQueue team-a-cq, wait time since queued was 1s
team-a        26m         Normal    Admitted                       workload/job-s3-low-02-37e08    Admitted by ClusterQueue team-a-cq, wait time since reservation was 1s
team-a        25m         Normal    EvictedDueToPreempted          workload/job-s3-low-02-37e08    Preempted to accommodate a workload (UID: af9be811-82ac-430a-af36-676827035c7b, JobUID: e03d1819-b26e-4859-b530-b761fdd5c3b9) due to prioritization in the ClusterQueue; preemptor path: /gpu-pool/team-a-cq; preemptee path: /gpu-pool/team-a-cq
team-a        25m         Normal    Preempted                      workload/job-s3-low-02-37e08    Preempted to accommodate a workload (UID: af9be811-82ac-430a-af36-676827035c7b, JobUID: e03d1819-b26e-4859-b530-b761fdd5c3b9) due to prioritization in the ClusterQueue; preemptor path: /gpu-pool/team-a-cq; preemptee path: /gpu-pool/team-a-cq; preemptor effective priority: 1000 (base: 1000, boost: 0); preemptee effective priority: 100 (base: 100, boost: 0)
team-a        25m         Normal    QuotaReserved                  workload/job-s3-low-02-37e08    Quota reserved in ClusterQueue team-a-cq, wait time since queued was 32s
team-a        25m         Normal    Admitted                       workload/job-s3-low-02-37e08    Admitted by ClusterQueue team-a-cq, wait time since reservation was 0s
team-a        2m22s       Normal    QuotaReserved                  workload/job-s3-low-02-c3b01    Quota reserved in ClusterQueue team-a-cq, wait time since queued was 1s
team-a        2m22s       Normal    Admitted                       workload/job-s3-low-02-c3b01    Admitted by ClusterQueue team-a-cq, wait time since reservation was 1s
team-a        13m         Normal    QuotaReserved                  workload/job-s4-a-01-aacb3      Quota reserved in ClusterQueue team-a-cq, wait time since queued was 0s
team-a        13m         Normal    Admitted                       workload/job-s4-a-01-aacb3      Admitted by ClusterQueue team-a-cq, wait time since reservation was 0s
team-a        23m         Normal    QuotaReserved                  workload/job-s4-a-01-fb89c      Quota reserved in ClusterQueue team-a-cq, wait time since queued was 1s
team-a        23m         Normal    Admitted                       workload/job-s4-a-01-fb89c      Admitted by ClusterQueue team-a-cq, wait time since reservation was 1s
team-a        23m         Normal    QuotaReserved                  workload/job-s4-a-02-55f07      Quota reserved in ClusterQueue team-a-cq, wait time since queued was 1s
team-a        23m         Normal    Admitted                       workload/job-s4-a-02-55f07      Admitted by ClusterQueue team-a-cq, wait time since reservation was 1s
team-a        13m         Normal    QuotaReserved                  workload/job-s4-a-02-c124b      Quota reserved in ClusterQueue team-a-cq, wait time since queued was 0s
team-a        13m         Normal    Admitted                       workload/job-s4-a-02-c124b      Admitted by ClusterQueue team-a-cq, wait time since reservation was 0s
team-a        21m         Normal    QuotaReserved                  workload/job-s4-a-03-5bcc9      Quota reserved in ClusterQueue team-a-cq, wait time since queued was 123s
team-a        21m         Normal    Admitted                       workload/job-s4-a-03-5bcc9      Admitted by ClusterQueue team-a-cq, wait time since reservation was 1s
team-a        10m         Normal    QuotaReserved                  workload/job-s4-a-03-d66ef      Quota reserved in ClusterQueue team-a-cq, wait time since queued was 122s
team-a        10m         Normal    Admitted                       workload/job-s4-a-03-d66ef      Admitted by ClusterQueue team-a-cq, wait time since reservation was 0s
team-a        10m         Normal    QuotaReserved                  workload/job-s4-a-04-04665      Quota reserved in ClusterQueue team-a-cq, wait time since queued was 122s
team-a        10m         Normal    Admitted                       workload/job-s4-a-04-04665      Admitted by ClusterQueue team-a-cq, wait time since reservation was 0s
team-a        21m         Normal    QuotaReserved                  workload/job-s4-a-04-e1741      Quota reserved in ClusterQueue team-a-cq, wait time since queued was 123s
team-a        21m         Normal    Admitted                       workload/job-s4-a-04-e1741      Admitted by ClusterQueue team-a-cq, wait time since reservation was 1s
team-a        32m         Normal    QuotaReserved                  workload/job-t1-01-b361d        Quota reserved in ClusterQueue team-a-cq, wait time since queued was 1s
team-a        32m         Normal    Admitted                       workload/job-t1-01-b361d        Admitted by ClusterQueue team-a-cq, wait time since reservation was 1s
team-a        32m         Normal    Started                        job/s1-a-01                     Admitted by clusterQueue team-a-cq
team-b        2m22s       Normal    Started                        job/s3-b-02                     Admitted by clusterQueue team-b-cq
team-b        13m         Normal    Started                        job/s3-b-02                     Admitted by clusterQueue team-b-cq
team-a        31m         Normal    Stopped                        job/s1-a-01                     Preempted to accommodate a workload (UID: 813077fb-6851-4f72-9b25-e107e159191e, JobUID: cc830d49-ddd7-4188-b6c3-ebad619ade6c) due to reclamation within the cohort; preemptor path: /gpu-pool/team-b-cq; preemptee path: /gpu-pool/team-a-cq
team-a        30m         Normal    Started                        job/s1-a-01                     Admitted by clusterQueue team-a-cq
team-b        26m         Normal    Started                        job/s3-b-02                     Admitted by clusterQueue team-b-cq
team-a        20m         Normal    Started                        job/s1-a-01                     Admitted by clusterQueue team-a-cq
team-a        19m         Normal    Stopped                        job/s1-a-01                     Preempted to accommodate a workload (UID: d64a966b-b291-4971-8605-83cf5d4a68ae, JobUID: 184db061-5915-4196-a699-b08f255b7b60) due to reclamation within the cohort; preemptor path: /gpu-pool/team-b-cq; preemptee path: /gpu-pool/team-a-cq
team-a        18m         Normal    Started                        job/s1-a-01                     Admitted by clusterQueue team-a-cq
team-b        2m22s       Normal    Started                        job/s3-b-01                     Admitted by clusterQueue team-b-cq
team-a        8m27s       Normal    Started                        job/s1-a-01                     Admitted by clusterQueue team-a-cq
team-b        13m         Normal    Started                        job/s3-b-01                     Admitted by clusterQueue team-b-cq
team-a        32m         Normal    Started                        job/s1-a-02                     Admitted by clusterQueue team-a-cq
team-b        26m         Normal    Started                        job/s3-b-01                     Admitted by clusterQueue team-b-cq
team-a        31m         Normal    Stopped                        job/s1-a-02                     Preempted to accommodate a workload (UID: ff1bdb74-d239-4fc0-8909-d3727254066e, JobUID: 3cea9334-971d-46ce-abaf-92e7178c26f8) due to reclamation within the cohort; preemptor path: /gpu-pool/team-b-cq; preemptee path: /gpu-pool/team-a-cq
team-a        30m         Normal    Started                        job/s1-a-02                     Admitted by clusterQueue team-a-cq
team-b        7m55s       Normal    Started                        job/s2-b-02                     Admitted by clusterQueue team-b-cq
team-b        19m         Normal    Started                        job/s2-b-02                     Admitted by clusterQueue team-b-cq
team-a        8m27s       Normal    Started                        job/s1-a-02                     Admitted by clusterQueue team-a-cq
team-b        31m         Normal    Started                        job/s2-b-02                     Admitted by clusterQueue team-b-cq
team-a        7m56s       Normal    Stopped                        job/s1-a-02                     Preempted to accommodate a workload (UID: 255f47e5-f138-4028-a784-ceb9eb01cc6c, JobUID: 8e73496a-b30d-4dd4-9eca-23cc62e6aeff) due to reclamation within the cohort; preemptor path: /gpu-pool/team-b-cq; preemptee path: /gpu-pool/team-a-cq
team-a        6m54s       Normal    Started                        job/s1-a-02                     Admitted by clusterQueue team-a-cq
team-b        7m56s       Normal    Started                        job/s2-b-01                     Admitted by clusterQueue team-b-cq
team-a        32m         Normal    Started                        job/s1-a-03                     Admitted by clusterQueue team-a-cq
team-a        20m         Normal    Started                        job/s1-a-03                     Admitted by clusterQueue team-a-cq
team-b        19m         Normal    Started                        job/s2-b-01                     Admitted by clusterQueue team-b-cq
team-b        31m         Normal    Started                        job/s2-b-01                     Admitted by clusterQueue team-b-cq
team-a        8m27s       Normal    Started                        job/s1-a-03                     Admitted by clusterQueue team-a-cq
team-a        7m55s       Normal    Stopped                        job/s1-a-03                     Preempted to accommodate a workload (UID: 2a833217-d9c8-4e9d-a8cd-eb98d862554a, JobUID: fe239855-686a-4ab5-974c-ef89b7c55d1a) due to reclamation within the cohort; preemptor path: /gpu-pool/team-b-cq; preemptee path: /gpu-pool/team-a-cq
team-a        6m52s       Normal    Started                        job/s1-a-03                     Admitted by clusterQueue team-a-cq
team-b        26m         Normal    Admitted                       workload/job-s3-b-02-71343      Admitted by ClusterQueue team-b-cq, wait time since reservation was 1s
team-b        26m         Normal    QuotaReserved                  workload/job-s3-b-02-71343      Quota reserved in ClusterQueue team-b-cq, wait time since queued was 1s
team-a        32m         Normal    Started                        job/s1-a-04                     Admitted by clusterQueue team-a-cq
team-b        13m         Normal    Admitted                       workload/job-s3-b-02-24dec      Admitted by ClusterQueue team-b-cq, wait time since reservation was 0s
team-b        13m         Normal    QuotaReserved                  workload/job-s3-b-02-24dec      Quota reserved in ClusterQueue team-b-cq, wait time since queued was 0s
team-b        2m22s       Normal    Admitted                       workload/job-s3-b-02-1a950      Admitted by ClusterQueue team-b-cq, wait time since reservation was 0s
team-b        2m22s       Normal    QuotaReserved                  workload/job-s3-b-02-1a950      Quota reserved in ClusterQueue team-b-cq, wait time since queued was 0s
team-a        20m         Normal    Started                        job/s1-a-04                     Admitted by clusterQueue team-a-cq
team-b        26m         Normal    Admitted                       workload/job-s3-b-01-fc136      Admitted by ClusterQueue team-b-cq, wait time since reservation was 1s
team-b        26m         Normal    QuotaReserved                  workload/job-s3-b-01-fc136      Quota reserved in ClusterQueue team-b-cq, wait time since queued was 1s
team-b        2m22s       Normal    Admitted                       workload/job-s3-b-01-72825      Admitted by ClusterQueue team-b-cq, wait time since reservation was 0s
team-a        19m         Normal    Stopped                        job/s1-a-04                     Preempted to accommodate a workload (UID: e37bba9e-9b8d-40b4-abec-2449d489cb83, JobUID: 3f8c2b68-f2f8-4919-84db-3b462d43c73f) due to reclamation within the cohort; preemptor path: /gpu-pool/team-b-cq; preemptee path: /gpu-pool/team-a-cq
team-a        18m         Normal    Started                        job/s1-a-04                     Admitted by clusterQueue team-a-cq
team-b        2m22s       Normal    QuotaReserved                  workload/job-s3-b-01-72825      Quota reserved in ClusterQueue team-b-cq, wait time since queued was 0s
team-b        13m         Normal    Admitted                       workload/job-s3-b-01-03792      Admitted by ClusterQueue team-b-cq, wait time since reservation was 0s
team-b        13m         Normal    QuotaReserved                  workload/job-s3-b-01-03792      Quota reserved in ClusterQueue team-b-cq, wait time since queued was 0s
team-a        8m27s       Normal    Started                        job/s1-a-04                     Admitted by clusterQueue team-a-cq
team-b        31m         Normal    Admitted                       workload/job-s2-b-02-aabfc      Admitted by ClusterQueue team-b-cq, wait time since reservation was 1s
team-b        31m         Normal    QuotaReserved                  workload/job-s2-b-02-aabfc      Quota reserved in ClusterQueue team-b-cq, wait time since queued was 3s
team-b        31m         Warning   WaitingForPreemptedWorkloads   workload/job-s2-b-02-aabfc      couldn't assign flavors to pod set main: insufficient unused quota for nvidia.com/gpu in flavor gpu-node, 1 more needed. Pending the preemption of 1 workload(s)
team-b        31m         Warning   WaitingForPreemptedWorkloads   workload/job-s2-b-02-aabfc      couldn't assign flavors to pod set main: insufficient unused quota for nvidia.com/gpu in flavor gpu-node, 1 more needed. Pending the preemption of 1 workload(s)
team-a        25m         Normal    Started                        job/s3-high-01                  Admitted by clusterQueue team-a-cq
team-b        31m         Normal    PreemptedWorkload              workload/job-s2-b-02-aabfc      Preempted workload team-a/job-s1-a-02-c1d3a (UID: 596cf3e2-a27f-4076-957a-bccb99d83054) in ClusterQueue team-a-cq; preemptor effective priority: 100 (base: 100, boost: 0); preemptee effective priority: 100 (base: 100, boost: 0)
team-b        19m         Normal    Admitted                       workload/job-s2-b-02-73e70      Admitted by ClusterQueue team-b-cq, wait time since reservation was 0s
team-b        19m         Normal    QuotaReserved                  workload/job-s2-b-02-73e70      Quota reserved in ClusterQueue team-b-cq, wait time since queued was 2s
team-b        19m         Warning   WaitingForPreemptedWorkloads   workload/job-s2-b-02-73e70      couldn't assign flavors to pod set main: insufficient unused quota for nvidia.com/gpu in flavor gpu-node, 1 more needed. Pending the preemption of 1 workload(s)
team-a        13m         Normal    Started                        job/s3-high-01                  Admitted by clusterQueue team-a-cq
team-b        19m         Warning   WaitingForPreemptedWorkloads   workload/job-s2-b-02-73e70      couldn't assign flavors to pod set main: insufficient unused quota for nvidia.com/gpu in flavor gpu-node, 1 more needed. Pending the preemption of 1 workload(s)
team-b        19m         Normal    PreemptedWorkload              workload/job-s2-b-02-73e70      Preempted workload team-a/job-s1-a-04-2fce2 (UID: 83c258d9-d8a1-490f-941a-7e1e4909dfc6) in ClusterQueue team-a-cq; preemptor effective priority: 100 (base: 100, boost: 0); preemptee effective priority: 100 (base: 100, boost: 0)
team-b        7m55s       Normal    Admitted                       workload/job-s2-b-02-309e8      Admitted by ClusterQueue team-b-cq, wait time since reservation was 1s
team-a        2m5s        Normal    Started                        job/s3-high-01                  Admitted by clusterQueue team-a-cq
team-b        7m55s       Normal    QuotaReserved                  workload/job-s2-b-02-309e8      Quota reserved in ClusterQueue team-b-cq, wait time since queued was 3s
team-b        7m55s       Warning   WaitingForPreemptedWorkloads   workload/job-s2-b-02-309e8      couldn't assign flavors to pod set main: insufficient unused quota for nvidia.com/gpu in flavor gpu-node, 1 more needed. Pending the preemption of 1 workload(s)
team-b        7m56s       Warning   WaitingForPreemptedWorkloads   workload/job-s2-b-02-309e8      couldn't assign flavors to pod set main: insufficient unused quota for nvidia.com/gpu in flavor gpu-node, 1 more needed. Pending the preemption of 1 workload(s)
team-b        7m56s       Normal    PreemptedWorkload              workload/job-s2-b-02-309e8      Preempted workload team-a/job-s1-a-03-7ddb8 (UID: 28a1abc1-e405-42b6-9873-8a0b7b35365e) in ClusterQueue team-a-cq; preemptor effective priority: 100 (base: 100, boost: 0); preemptee effective priority: 100 (base: 100, boost: 0)
team-a        26m         Normal    Started                        job/s3-low-01                   Admitted by clusterQueue team-a-cq
team-b        31m         Normal    Admitted                       workload/job-s2-b-01-dd91e      Admitted by ClusterQueue team-b-cq, wait time since reservation was 1s
team-b        31m         Normal    QuotaReserved                  workload/job-s2-b-01-dd91e      Quota reserved in ClusterQueue team-b-cq, wait time since queued was 2s
team-b        31m         Warning   WaitingForPreemptedWorkloads   workload/job-s2-b-01-dd91e      couldn't assign flavors to pod set main: insufficient unused quota for nvidia.com/gpu in flavor gpu-node, 1 more needed. Pending the preemption of 1 workload(s)
team-b        31m         Warning   WaitingForPreemptedWorkloads   workload/job-s2-b-01-dd91e      couldn't assign flavors to pod set main: insufficient unused quota for nvidia.com/gpu in flavor gpu-node, 1 more needed. Pending the preemption of 1 workload(s)
team-a        13m         Normal    Started                        job/s3-low-01                   Admitted by clusterQueue team-a-cq
team-b        31m         Normal    PreemptedWorkload              workload/job-s2-b-01-dd91e      Preempted workload team-a/job-s1-a-01-f3da4 (UID: 3235532d-1c28-43bf-9b57-d355457159a9) in ClusterQueue team-a-cq; preemptor effective priority: 100 (base: 100, boost: 0); preemptee effective priority: 100 (base: 100, boost: 0)
team-b        7m56s       Normal    Admitted                       workload/job-s2-b-01-ca40e      Admitted by ClusterQueue team-b-cq, wait time since reservation was 1s
team-b        7m56s       Normal    QuotaReserved                  workload/job-s2-b-01-ca40e      Quota reserved in ClusterQueue team-b-cq, wait time since queued was 2s
team-a        2m22s       Normal    Started                        job/s3-low-01                   Admitted by clusterQueue team-a-cq
team-b        7m56s       Warning   WaitingForPreemptedWorkloads   workload/job-s2-b-01-ca40e      couldn't assign flavors to pod set main: insufficient unused quota for nvidia.com/gpu in flavor gpu-node, 1 more needed. Pending the preemption of 1 workload(s)
team-b        7m57s       Warning   WaitingForPreemptedWorkloads   workload/job-s2-b-01-ca40e      couldn't assign flavors to pod set main: insufficient unused quota for nvidia.com/gpu in flavor gpu-node, 1 more needed. Pending the preemption of 1 workload(s)
team-b        7m57s       Normal    PreemptedWorkload              workload/job-s2-b-01-ca40e      Preempted workload team-a/job-s1-a-02-a2320 (UID: 1db689ff-3330-4d72-a772-d2959f2e4536) in ClusterQueue team-a-cq; preemptor effective priority: 100 (base: 100, boost: 0); preemptee effective priority: 100 (base: 100, boost: 0)
team-a        2m6s        Normal    Stopped                        job/s3-low-01                   Preempted to accommodate a workload (UID: 6d2f0a34-2b45-457d-8fdd-aa2292c05e31, JobUID: 703a47be-70fd-46c1-b505-49ae790bc190) due to prioritization in the ClusterQueue; preemptor path: /gpu-pool/team-a-cq; preemptee path: /gpu-pool/team-a-cq
team-a        93s         Normal    Started                        job/s3-low-01                   Admitted by clusterQueue team-a-cq
team-b        19m         Normal    Admitted                       workload/job-s2-b-01-9d30d      Admitted by ClusterQueue team-b-cq, wait time since reservation was 0s
team-b        19m         Normal    QuotaReserved                  workload/job-s2-b-01-9d30d      Quota reserved in ClusterQueue team-b-cq, wait time since queued was 1s
team-b        19m         Warning   WaitingForPreemptedWorkloads   workload/job-s2-b-01-9d30d      couldn't assign flavors to pod set main: insufficient unused quota for nvidia.com/gpu in flavor gpu-node, 1 more needed. Pending the preemption of 1 workload(s)
team-a        26m         Normal    Started                        job/s3-low-02                   Admitted by clusterQueue team-a-cq
team-b        19m         Warning   WaitingForPreemptedWorkloads   workload/job-s2-b-01-9d30d      couldn't assign flavors to pod set main: insufficient unused quota for nvidia.com/gpu in flavor gpu-node, 1 more needed. Pending the preemption of 1 workload(s)
team-a        23m         Normal    Started                        job/s4-a-02                     Admitted by clusterQueue team-a-cq
team-a        25m         Normal    Stopped                        job/s3-low-02                   Preempted to accommodate a workload (UID: af9be811-82ac-430a-af36-676827035c7b, JobUID: e03d1819-b26e-4859-b530-b761fdd5c3b9) due to prioritization in the ClusterQueue; preemptor path: /gpu-pool/team-a-cq; preemptee path: /gpu-pool/team-a-cq
team-a        25m         Normal    Started                        job/s3-low-02                   Admitted by clusterQueue team-a-cq
team-a        32m         Normal    Started                        job/t1-01                       Admitted by clusterQueue team-a-cq
team-a        13m         Normal    Started                        job/s3-low-02                   Admitted by clusterQueue team-a-cq
team-a        13m         Normal    Stopped                        job/s3-low-02                   Preempted to accommodate a workload (UID: 2f56e49c-4011-4e39-8752-5023b91b4dc0, JobUID: 324bd808-fefd-4d77-952a-d09e6d2cc3ef) due to prioritization in the ClusterQueue; preemptor path: /gpu-pool/team-a-cq; preemptee path: /gpu-pool/team-a-cq
team-a        13m         Normal    Started                        job/s3-low-02                   Admitted by clusterQueue team-a-cq
team-a        10m         Normal    Started                        job/s4-a-04                     Admitted by clusterQueue team-a-cq
team-a        2m22s       Normal    Started                        job/s3-low-02                   Admitted by clusterQueue team-a-cq
team-a        21m         Normal    Started                        job/s4-a-04                     Admitted by clusterQueue team-a-cq
team-a        23m         Normal    Started                        job/s4-a-01                     Admitted by clusterQueue team-a-cq
team-a        10m         Normal    Started                        job/s4-a-03                     Admitted by clusterQueue team-a-cq
team-a        21m         Normal    Started                        job/s4-a-03                     Admitted by clusterQueue team-a-cq
team-a        13m         Normal    Started                        job/s4-a-01                     Admitted by clusterQueue team-a-cq
