team-a               9m28s       Normal    QuotaReserved                  workload/job-s3-low-02-a43f0                     Quota reserved in ClusterQueue team-a-cq, wait time since queued was 1s
team-a               2m5s        Normal    Started                        job/s1c-a-01                                     Admitted by clusterQueue team-a-cq
team-a               9m28s       Normal    Admitted                       workload/job-s3-low-02-a43f0                     Admitted by ClusterQueue team-a-cq, wait time since reservation was 1s
team-a               15m         Normal    Stopped                        job/s1-a-04                                      Preempted to accommodate a workload (UID: 1796b585-75e3-4462-b2cf-6c51d5811d63, JobUID: 33a965fe-fc90-498e-94e9-2661142d975b) due to reclamation within the cohort; preemptor path: /gpu-pool/team-b-cq; preemptee path: /gpu-pool/team-a-cq
team-a               2m5s        Normal    Started                        job/s1c-a-02                                     Admitted by clusterQueue team-a-cq
team-a               15m         Normal    Started                        job/s1-a-04                                      Admitted by clusterQueue team-a-cq
team-a               2m5s        Normal    Started                        job/s1c-a-03                                     Admitted by clusterQueue team-a-cq
team-a               35m         Normal    Started                        job/s1-a-04                                      Admitted by clusterQueue team-a-cq
team-a               2m5s        Normal    Started                        job/s1c-a-04                                     Admitted by clusterQueue team-a-cq
team-a               9m11s       Normal    Started                        job/s3-high-01                                   Admitted by clusterQueue team-a-cq
team-a               9m28s       Normal    Started                        job/s3-low-01                                    Admitted by clusterQueue team-a-cq
team-a               9m28s       Normal    Started                        job/s3-low-02                                    Admitted by clusterQueue team-a-cq
team-a               9m11s       Normal    Stopped                        job/s3-low-02                                    Preempted to accommodate a workload (UID: a5eb2ac6-d1bb-47f9-b9ae-9d2b503c3345, JobUID: be470671-97cc-4af6-b8cd-80edaeee73b9) due to prioritization in the ClusterQueue; preemptor path: /gpu-pool/team-a-cq; preemptee path: /gpu-pool/team-a-cq
team-a               8m33s       Normal    Started                        job/s3-low-02                                    Admitted by clusterQueue team-a-cq
team-a               15m         Normal    Started                        job/s1-a-03                                      Admitted by clusterQueue team-a-cq
team-a               6m44s       Normal    Started                        job/s4-a-01                                      Admitted by clusterQueue team-a-cq
team-a               33m         Normal    Started                        job/s1-a-03                                      Admitted by clusterQueue team-a-cq
team-a               34m         Normal    Stopped                        job/s1-a-03                                      Preempted to accommodate a workload (UID: 7b41f460-844a-432d-bf01-43fff61c5db6, JobUID: df20c4b9-f5fc-47ed-95a7-226fd360be56) due to reclamation within the cohort; preemptor path: /gpu-pool/team-b-cq; preemptee path: /gpu-pool/team-a-cq
team-a               35m         Normal    Started                        job/s1-a-03                                      Admitted by clusterQueue team-a-cq
team-a               6m44s       Normal    Started                        job/s4-a-02                                      Admitted by clusterQueue team-a-cq
team-a               4m39s       Normal    Started                        job/s4-a-03                                      Admitted by clusterQueue team-a-cq
team-a               4m39s       Normal    Started                        job/s4-a-04                                      Admitted by clusterQueue team-a-cq
team-b               15m         Normal    PreemptedWorkload              workload/job-s2-b-01-0a24f                       Preempted workload team-a/job-s1-a-01-c7921 (UID: 349e6598-7b8f-4ccb-95a2-92f39e346491) in ClusterQueue team-a-cq; preemptor effective priority: 100 (base: 100, boost: 0); preemptee effective priority: 100 (base: 100, boost: 0)
team-b               15m         Warning   WaitingForPreemptedWorkloads   workload/job-s2-b-01-0a24f                       couldn't assign flavors to pod set main: insufficient unused quota for nvidia.com/gpu in flavor gpu-node, 1 more needed. Pending the preemption of 1 workload(s)
team-b               15m         Warning   WaitingForPreemptedWorkloads   workload/job-s2-b-01-0a24f                       couldn't assign flavors to pod set main: insufficient unused quota for nvidia.com/gpu in flavor gpu-node, 1 more needed. Pending the preemption of 1 workload(s)
team-b               15m         Normal    QuotaReserved                  workload/job-s2-b-01-0a24f                       Quota reserved in ClusterQueue team-b-cq, wait time since queued was 2s
team-b               15m         Normal    Admitted                       workload/job-s2-b-01-0a24f                       Admitted by ClusterQueue team-b-cq, wait time since reservation was 1s
team-b               34m         Normal    PreemptedWorkload              workload/job-s2-b-01-f3667                       Preempted workload team-a/job-s1-a-03-521c5 (UID: 1a5a8305-a8c6-4ae0-a4f6-4ddf89c82f5b) in ClusterQueue team-a-cq; preemptor effective priority: 100 (base: 100, boost: 0); preemptee effective priority: 100 (base: 100, boost: 0)
team-b               34m         Warning   WaitingForPreemptedWorkloads   workload/job-s2-b-01-f3667                       couldn't assign flavors to pod set main: insufficient unused quota for nvidia.com/gpu in flavor gpu-node, 1 more needed. Pending the preemption of 1 workload(s)
team-b               34m         Warning   WaitingForPreemptedWorkloads   workload/job-s2-b-01-f3667                       couldn't assign flavors to pod set main: insufficient unused quota for nvidia.com/gpu in flavor gpu-node, 1 more needed. Pending the preemption of 1 workload(s)
team-a               15m         Normal    Started                        job/s1-a-02                                      Admitted by clusterQueue team-a-cq
team-b               34m         Normal    QuotaReserved                  workload/job-s2-b-01-f3667                       Quota reserved in ClusterQueue team-b-cq, wait time since queued was 2s
team-b               34m         Normal    Admitted                       workload/job-s2-b-01-f3667                       Admitted by ClusterQueue team-b-cq, wait time since reservation was 1s
team-a               35m         Normal    Started                        job/s1-a-02                                      Admitted by clusterQueue team-a-cq
team-b               15m         Normal    PreemptedWorkload              workload/job-s2-b-02-5b2e9                       Preempted workload team-a/job-s1-a-04-7e5b2 (UID: 6cac712f-dc99-4584-aede-8e864ac516f7) in ClusterQueue team-a-cq; preemptor effective priority: 100 (base: 100, boost: 0); preemptee effective priority: 100 (base: 100, boost: 0)
team-b               15m         Warning   WaitingForPreemptedWorkloads   workload/job-s2-b-02-5b2e9                       couldn't assign flavors to pod set main: insufficient unused quota for nvidia.com/gpu in flavor gpu-node, 1 more needed. Pending the preemption of 1 workload(s)
team-b               15m         Warning   WaitingForPreemptedWorkloads   workload/job-s2-b-02-5b2e9                       couldn't assign flavors to pod set main: insufficient unused quota for nvidia.com/gpu in flavor gpu-node, 1 more needed. Pending the preemption of 1 workload(s)
team-b               15m         Normal    QuotaReserved                  workload/job-s2-b-02-5b2e9                       Quota reserved in ClusterQueue team-b-cq, wait time since queued was 3s
team-b               15m         Normal    Admitted                       workload/job-s2-b-02-5b2e9                       Admitted by ClusterQueue team-b-cq, wait time since reservation was 0s
team-b               34m         Normal    PreemptedWorkload              workload/job-s2-b-02-738ad                       Preempted workload team-a/job-s1-a-01-7f98f (UID: b844ce65-66c2-4fc3-a5f8-ebfac92f6cb1) in ClusterQueue team-a-cq; preemptor effective priority: 100 (base: 100, boost: 0); preemptee effective priority: 100 (base: 100, boost: 0)
team-b               34m         Warning   WaitingForPreemptedWorkloads   workload/job-s2-b-02-738ad                       couldn't assign flavors to pod set main: insufficient unused quota for nvidia.com/gpu in flavor gpu-node, 1 more needed. Pending the preemption of 1 workload(s)
team-a               13m         Normal    Started                        job/s1-a-01                                      Admitted by clusterQueue team-a-cq
team-a               15m         Normal    Stopped                        job/s1-a-01                                      Preempted to accommodate a workload (UID: 5b8a9c3b-fac8-4aa6-9b8a-dd84175e2e71, JobUID: 54b6f380-1204-4f61-a9dd-1952b63dc034) due to reclamation within the cohort; preemptor path: /gpu-pool/team-b-cq; preemptee path: /gpu-pool/team-a-cq
team-b               34m         Warning   WaitingForPreemptedWorkloads   workload/job-s2-b-02-738ad                       couldn't assign flavors to pod set main: insufficient unused quota for nvidia.com/gpu in flavor gpu-node, 1 more needed. Pending the preemption of 1 workload(s)
team-b               34m         Normal    QuotaReserved                  workload/job-s2-b-02-738ad                       Quota reserved in ClusterQueue team-b-cq, wait time since queued was 3s
team-b               34m         Normal    Admitted                       workload/job-s2-b-02-738ad                       Admitted by ClusterQueue team-b-cq, wait time since reservation was 0s
team-a               15m         Normal    Started                        job/s1-a-01                                      Admitted by clusterQueue team-a-cq
team-a               35m         Normal    QuotaReserved                  workload/job-s1-a-01-7f98f                       Quota reserved in ClusterQueue team-a-cq, wait time since queued was 0s
team-a               35m         Normal    Admitted                       workload/job-s1-a-01-7f98f                       Admitted by ClusterQueue team-a-cq, wait time since reservation was 0s
team-a               34m         Normal    EvictedDueToPreempted          workload/job-s1-a-01-7f98f                       Preempted to accommodate a workload (UID: 02f4960e-7b04-4ee2-b965-e1deec0b4529, JobUID: 22d5b02f-f162-4cad-8a3c-686a6b02edbd) due to reclamation within the cohort; preemptor path: /gpu-pool/team-b-cq; preemptee path: /gpu-pool/team-a-cq
team-a               34m         Normal    Preempted                      workload/job-s1-a-01-7f98f                       Preempted to accommodate a workload (UID: 02f4960e-7b04-4ee2-b965-e1deec0b4529, JobUID: 22d5b02f-f162-4cad-8a3c-686a6b02edbd) due to reclamation within the cohort; preemptor path: /gpu-pool/team-b-cq; preemptee path: /gpu-pool/team-a-cq; preemptor effective priority: 100 (base: 100, boost: 0); preemptee effective priority: 100 (base: 100, boost: 0)
team-a               33m         Normal    QuotaReserved                  workload/job-s1-a-01-7f98f                       Quota reserved in ClusterQueue team-a-cq, wait time since queued was 68s; Flavors considered: main: gpu-node(Fit;borrow=1)
team-a               33m         Normal    Admitted                       workload/job-s1-a-01-7f98f                       Admitted by ClusterQueue team-a-cq, wait time since reservation was 1s
team-a               15m         Normal    QuotaReserved                  workload/job-s1-a-01-c7921                       Quota reserved in ClusterQueue team-a-cq, wait time since queued was 0s
team-a               15m         Normal    Admitted                       workload/job-s1-a-01-c7921                       Admitted by ClusterQueue team-a-cq, wait time since reservation was 0s
team-a               15m         Normal    EvictedDueToPreempted          workload/job-s1-a-01-c7921                       Preempted to accommodate a workload (UID: 5b8a9c3b-fac8-4aa6-9b8a-dd84175e2e71, JobUID: 54b6f380-1204-4f61-a9dd-1952b63dc034) due to reclamation within the cohort; preemptor path: /gpu-pool/team-b-cq; preemptee path: /gpu-pool/team-a-cq
team-a               15m         Normal    Preempted                      workload/job-s1-a-01-c7921                       Preempted to accommodate a workload (UID: 5b8a9c3b-fac8-4aa6-9b8a-dd84175e2e71, JobUID: 54b6f380-1204-4f61-a9dd-1952b63dc034) due to reclamation within the cohort; preemptor path: /gpu-pool/team-b-cq; preemptee path: /gpu-pool/team-a-cq; preemptor effective priority: 100 (base: 100, boost: 0); preemptee effective priority: 100 (base: 100, boost: 0)
team-a               13m         Normal    QuotaReserved                  workload/job-s1-a-01-c7921                       Quota reserved in ClusterQueue team-a-cq, wait time since queued was 70s; Flavors considered: main: gpu-node(Fit;borrow=1)
team-a               13m         Normal    Admitted                       workload/job-s1-a-01-c7921                       Admitted by ClusterQueue team-a-cq, wait time since reservation was 1s
team-a               35m         Normal    QuotaReserved                  workload/job-s1-a-02-b4d51                       Quota reserved in ClusterQueue team-a-cq, wait time since queued was 0s
team-a               35m         Normal    Admitted                       workload/job-s1-a-02-b4d51                       Admitted by ClusterQueue team-a-cq, wait time since reservation was 0s
team-a               15m         Normal    QuotaReserved                  workload/job-s1-a-02-db8df                       Quota reserved in ClusterQueue team-a-cq, wait time since queued was 0s
team-a               15m         Normal    Admitted                       workload/job-s1-a-02-db8df                       Admitted by ClusterQueue team-a-cq, wait time since reservation was 0s
team-a               35m         Normal    QuotaReserved                  workload/job-s1-a-03-521c5                       Quota reserved in ClusterQueue team-a-cq, wait time since queued was 0s; Flavors considered: main: gpu-node(Fit;borrow=1)
team-a               35m         Normal    Admitted                       workload/job-s1-a-03-521c5                       Admitted by ClusterQueue team-a-cq, wait time since reservation was 0s
team-a               34m         Normal    EvictedDueToPreempted          workload/job-s1-a-03-521c5                       Preempted to accommodate a workload (UID: 7b41f460-844a-432d-bf01-43fff61c5db6, JobUID: df20c4b9-f5fc-47ed-95a7-226fd360be56) due to reclamation within the cohort; preemptor path: /gpu-pool/team-b-cq; preemptee path: /gpu-pool/team-a-cq
team-a               34m         Normal    Preempted                      workload/job-s1-a-03-521c5                       Preempted to accommodate a workload (UID: 7b41f460-844a-432d-bf01-43fff61c5db6, JobUID: df20c4b9-f5fc-47ed-95a7-226fd360be56) due to reclamation within the cohort; preemptor path: /gpu-pool/team-b-cq; preemptee path: /gpu-pool/team-a-cq; preemptor effective priority: 100 (base: 100, boost: 0); preemptee effective priority: 100 (base: 100, boost: 0)
team-a               33m         Normal    QuotaReserved                  workload/job-s1-a-03-521c5                       Quota reserved in ClusterQueue team-a-cq, wait time since queued was 70s; Flavors considered: main: gpu-node(Fit;borrow=1)
team-a               33m         Normal    Admitted                       workload/job-s1-a-03-521c5                       Admitted by ClusterQueue team-a-cq, wait time since reservation was 1s
team-a               15m         Normal    QuotaReserved                  workload/job-s1-a-03-9d493                       Quota reserved in ClusterQueue team-a-cq, wait time since queued was 0s; Flavors considered: main: gpu-node(Fit;borrow=1)
team-a               15m         Normal    Admitted                       workload/job-s1-a-03-9d493                       Admitted by ClusterQueue team-a-cq, wait time since reservation was 0s
team-a               15m         Normal    QuotaReserved                  workload/job-s1-a-04-7e5b2                       Quota reserved in ClusterQueue team-a-cq, wait time since queued was 0s; Flavors considered: main: gpu-node(Fit;borrow=1)
team-a               15m         Normal    Admitted                       workload/job-s1-a-04-7e5b2                       Admitted by ClusterQueue team-a-cq, wait time since reservation was 0s
team-a               15m         Normal    EvictedDueToPreempted          workload/job-s1-a-04-7e5b2                       Preempted to accommodate a workload (UID: 1796b585-75e3-4462-b2cf-6c51d5811d63, JobUID: 33a965fe-fc90-498e-94e9-2661142d975b) due to reclamation within the cohort; preemptor path: /gpu-pool/team-b-cq; preemptee path: /gpu-pool/team-a-cq
team-a               15m         Normal    Preempted                      workload/job-s1-a-04-7e5b2                       Preempted to accommodate a workload (UID: 1796b585-75e3-4462-b2cf-6c51d5811d63, JobUID: 33a965fe-fc90-498e-94e9-2661142d975b) due to reclamation within the cohort; preemptor path: /gpu-pool/team-b-cq; preemptee path: /gpu-pool/team-a-cq; preemptor effective priority: 100 (base: 100, boost: 0); preemptee effective priority: 100 (base: 100, boost: 0)
team-a               13m         Normal    QuotaReserved                  workload/job-s1-a-04-7e5b2                       Quota reserved in ClusterQueue team-a-cq, wait time since queued was 69s; Flavors considered: main: gpu-node(Fit;borrow=1)
team-a               13m         Normal    Admitted                       workload/job-s1-a-04-7e5b2                       Admitted by ClusterQueue team-a-cq, wait time since reservation was 1s
team-a               35m         Normal    QuotaReserved                  workload/job-s1-a-04-f254a                       Quota reserved in ClusterQueue team-a-cq, wait time since queued was 0s; Flavors considered: main: gpu-node(Fit;borrow=1)
team-a               35m         Normal    Admitted                       workload/job-s1-a-04-f254a                       Admitted by ClusterQueue team-a-cq, wait time since reservation was 0s
team-a               2m5s        Normal    QuotaReserved                  workload/job-s1c-a-01-5fc1e                      Quota reserved in ClusterQueue team-a-cq, wait time since queued was 1s
team-a               2m5s        Normal    Admitted                       workload/job-s1c-a-01-5fc1e                      Admitted by ClusterQueue team-a-cq, wait time since reservation was 1s
team-a               2m5s        Normal    QuotaReserved                  workload/job-s1c-a-02-f9f11                      Quota reserved in ClusterQueue team-a-cq, wait time since queued was 1s
team-a               2m5s        Normal    Admitted                       workload/job-s1c-a-02-f9f11                      Admitted by ClusterQueue team-a-cq, wait time since reservation was 1s
team-a               2m5s        Normal    QuotaReserved                  workload/job-s1c-a-03-ea299                      Quota reserved in ClusterQueue team-a-cq, wait time since queued was 1s; Flavors considered: main: gpu-node(Fit;borrow=1)
team-a               2m5s        Normal    Admitted                       workload/job-s1c-a-03-ea299                      Admitted by ClusterQueue team-a-cq, wait time since reservation was 1s
team-a               2m5s        Normal    QuotaReserved                  workload/job-s1c-a-04-5dcb8                      Quota reserved in ClusterQueue team-a-cq, wait time since queued was 0s; Flavors considered: main: gpu-node(Fit;borrow=1)
team-a               2m5s        Normal    Admitted                       workload/job-s1c-a-04-5dcb8                      Admitted by ClusterQueue team-a-cq, wait time since reservation was 0s
team-a               9m12s       Normal    PreemptedWorkload              workload/job-s3-high-01-14e84                    Preempted workload team-a/job-s3-low-02-a43f0 (UID: 037ee2f9-ae61-4c00-9bb6-8958e09be55f) in ClusterQueue team-a-cq; preemptor effective priority: 1000 (base: 1000, boost: 0); preemptee effective priority: 100 (base: 100, boost: 0)
team-a               9m12s       Warning   WaitingForPreemptedWorkloads   workload/job-s3-high-01-14e84                    couldn't assign flavors to pod set main: insufficient unused quota for nvidia.com/gpu in flavor gpu-node, 1 more needed. Pending the preemption of 1 workload(s)
team-a               9m11s       Warning   WaitingForPreemptedWorkloads   workload/job-s3-high-01-14e84                    couldn't assign flavors to pod set main: insufficient unused quota for nvidia.com/gpu in flavor gpu-node, 1 more needed. Pending the preemption of 1 workload(s)
team-a               9m11s       Normal    QuotaReserved                  workload/job-s3-high-01-14e84                    Quota reserved in ClusterQueue team-a-cq, wait time since queued was 2s
team-a               9m11s       Normal    Admitted                       workload/job-s3-high-01-14e84                    Admitted by ClusterQueue team-a-cq, wait time since reservation was 1s
team-a               9m28s       Normal    QuotaReserved                  workload/job-s3-low-01-2b7af                     Quota reserved in ClusterQueue team-a-cq, wait time since queued was 1s
team-a               9m28s       Normal    Admitted                       workload/job-s3-low-01-2b7af                     Admitted by ClusterQueue team-a-cq, wait time since reservation was 1s
team-b               9m29s       Normal    QuotaReserved                  workload/job-s3-b-01-1e603                       Quota reserved in ClusterQueue team-b-cq, wait time since queued was 1s
team-a               13m         Normal    Started                        job/s1-a-04                                      Admitted by clusterQueue team-a-cq
team-a               9m12s       Normal    Preempted                      workload/job-s3-low-02-a43f0                     Preempted to accommodate a workload (UID: a5eb2ac6-d1bb-47f9-b9ae-9d2b503c3345, JobUID: be470671-97cc-4af6-b8cd-80edaeee73b9) due to prioritization in the ClusterQueue; preemptor path: /gpu-pool/team-a-cq; preemptee path: /gpu-pool/team-a-cq; preemptor effective priority: 1000 (base: 1000, boost: 0); preemptee effective priority: 100 (base: 100, boost: 0)
team-a               8m33s       Normal    QuotaReserved                  workload/job-s3-low-02-a43f0                     Quota reserved in ClusterQueue team-a-cq, wait time since queued was 40s
team-a               8m33s       Normal    Admitted                       workload/job-s3-low-02-a43f0                     Admitted by ClusterQueue team-a-cq, wait time since reservation was 1s
team-a               6m45s       Normal    QuotaReserved                  workload/job-s4-a-01-bdd36                       Quota reserved in ClusterQueue team-a-cq, wait time since queued was 1s
team-a               6m45s       Normal    Admitted                       workload/job-s4-a-01-bdd36                       Admitted by ClusterQueue team-a-cq, wait time since reservation was 1s
team-a               6m44s       Normal    QuotaReserved                  workload/job-s4-a-02-d2ba3                       Quota reserved in ClusterQueue team-a-cq, wait time since queued was 1s
team-a               6m44s       Normal    Admitted                       workload/job-s4-a-02-d2ba3                       Admitted by ClusterQueue team-a-cq, wait time since reservation was 1s
team-a               4m39s       Normal    QuotaReserved                  workload/job-s4-a-03-baf73                       Quota reserved in ClusterQueue team-a-cq, wait time since queued was 126s
team-a               4m39s       Normal    Admitted                       workload/job-s4-a-03-baf73                       Admitted by ClusterQueue team-a-cq, wait time since reservation was 1s
team-a               4m39s       Normal    QuotaReserved                  workload/job-s4-a-04-aaa81                       Quota reserved in ClusterQueue team-a-cq, wait time since queued was 126s
team-a               4m39s       Normal    Admitted                       workload/job-s4-a-04-aaa81                       Admitted by ClusterQueue team-a-cq, wait time since reservation was 1s
team-b               9m29s       Normal    Admitted                       workload/job-s3-b-01-1e603                       Admitted by ClusterQueue team-b-cq, wait time since reservation was 1s
team-b               9m29s       Normal    Started                        job/s3-b-02                                      Admitted by clusterQueue team-b-cq
team-b               9m29s       Normal    Started                        job/s3-b-01                                      Admitted by clusterQueue team-b-cq
team-b               15m         Normal    Started                        job/s2-b-02                                      Admitted by clusterQueue team-b-cq
team-b               34m         Normal    Started                        job/s2-b-02                                      Admitted by clusterQueue team-b-cq
team-b               15m         Normal    Started                        job/s2-b-01                                      Admitted by clusterQueue team-b-cq
team-b               34m         Normal    Started                        job/s2-b-01                                      Admitted by clusterQueue team-b-cq
team-a               35m         Normal    Started                        job/s1-a-01                                      Admitted by clusterQueue team-a-cq
team-b               9m29s       Normal    QuotaReserved                  workload/job-s3-b-02-da79d                       Quota reserved in ClusterQueue team-b-cq, wait time since queued was 1s
team-a               9m12s       Normal    EvictedDueToPreempted          workload/job-s3-low-02-a43f0                     Preempted to accommodate a workload (UID: a5eb2ac6-d1bb-47f9-b9ae-9d2b503c3345, JobUID: be470671-97cc-4af6-b8cd-80edaeee73b9) due to prioritization in the ClusterQueue; preemptor path: /gpu-pool/team-a-cq; preemptee path: /gpu-pool/team-a-cq
team-b               9m29s       Normal    Admitted                       workload/job-s3-b-02-da79d                       Admitted by ClusterQueue team-b-cq, wait time since reservation was 1s
team-a               34m         Normal    Stopped                        job/s1-a-01                                      Preempted to accommodate a workload (UID: 02f4960e-7b04-4ee2-b965-e1deec0b4529, JobUID: 22d5b02f-f162-4cad-8a3c-686a6b02edbd) due to reclamation within the cohort; preemptor path: /gpu-pool/team-b-cq; preemptee path: /gpu-pool/team-a-cq
team-a               33m         Normal    Started                        job/s1-a-01                                      Admitted by clusterQueue team-a-cq
local-path-storage   37m         Warning   FailedScheduling               pod/local-path-provisioner-75f7fc7dc5-nwfvw      0/1 nodes are available: 1 node(s) had untolerated taint(s). preemption: 0/1 nodes are available: 1 Preemption is not helpful for scheduling.
kube-system          37m         Warning   FailedScheduling               pod/coredns-559f6c778d-c2scb                     0/1 nodes are available: 1 node(s) had untolerated taint(s). preemption: 0/1 nodes are available: 1 Preemption is not helpful for scheduling.
kube-system          37m         Warning   FailedScheduling               pod/coredns-559f6c778d-6swc5                     0/1 nodes are available: 1 node(s) had untolerated taint(s). preemption: 0/1 nodes are available: 1 Preemption is not helpful for scheduling.
kueue-system         36m         Warning   FailedScheduling               pod/kueue-controller-manager-76b44cd5c4-ddcql    0/3 nodes are available: 3 node(s) had untolerated taint(s). preemption: 0/3 nodes are available: 3 Preemption is not helpful for scheduling.
team-b               34m         Warning   FailedScheduling               pod/s2-b-01-7h565                                0/3 nodes are available: 1 node(s) had untolerated taint(s), 2 Insufficient nvidia.com/gpu. preemption: 0/3 nodes are available: 1 Preemption is not helpful for scheduling, 2 No preemption victims found for incoming pod.
team-b               34m         Warning   FailedScheduling               pod/s2-b-02-jcgvq                                0/3 nodes are available: 1 node(s) had untolerated taint(s), 2 Insufficient nvidia.com/gpu. preemption: 0/3 nodes are available: 1 Preemption is not helpful for scheduling, 2 No preemption victims found for incoming pod.
team-b               15m         Warning   FailedScheduling               pod/s2-b-01-thq9l                                0/3 nodes are available: 1 node(s) had untolerated taint(s), 2 Insufficient nvidia.com/gpu. preemption: 0/3 nodes are available: 1 Preemption is not helpful for scheduling, 2 No preemption victims found for incoming pod.
team-b               14m         Warning   FailedScheduling               pod/s2-b-02-gwzth                                0/3 nodes are available: 1 node(s) had untolerated taint(s), 2 Insufficient nvidia.com/gpu. preemption: 0/3 nodes are available: 1 Preemption is not helpful for scheduling, 2 No preemption victims found for incoming pod.
team-a               9m12s       Warning   FailedScheduling               pod/s3-high-01-7r7n8                             0/3 nodes are available: 1 node(s) had untolerated taint(s), 2 Insufficient nvidia.com/gpu. preemption: 0/3 nodes are available: 1 Preemption is not helpful for scheduling, 2 No preemption victims found for incoming pod.
